Workbook

Sheet AH
AQ1: Vtr+10 | AR1: Vtr+20
B2: VTR [km/h] | C2: 40 | E2: c [m] | F2: 5 | AQ2: =C2+10 -> 50 | AR2: =C2+20 -> 60
B4: PUNTO | C4: COORDENADAS | E4: Altura | F4: DISTANCIA [m] | G4: PENDIENTE [%] | H4: SENTIDO | I4: Acimut [°] | J4: ACIMUT [° ' ''] | K4: Deflexion | L4: DEFLEXION - Δ | M4: VCH [km/h] | N4: Rmin [m] | O4: Gc max [°] | P4: Gc max [° ' ''] | Q4: Gredondo [°] | R4: Gredondo [° ' ''] | S4: Rmin Definitivo [m] | T4: DISTDefinitiva [m] | U4: T [m] | V4: Lc [m] | W4: ABSCISAS
C5: NORTE | D5: ESTE | K5: [°] | L5: [° ' ''] | W5: PC | X5: PT
B6: P1 (Inicial) | C6: 1190813 | D6: 837789.62 | E6: 1644 | W6: 0 | AC6: a2 | AD6: a3 | AE6: a4 | AF6: a5 | AG6: b1 | AH6: b2 | AI6: b3 | AJ6: b4 | AK6: b5 | AL6: c1 | AM6: c2 | AN6: c3 | AO6: c4 | AP6: c5
F7: =SQRT((C8-C6)^2+(D8-D6)^2) -> 195.04761 | G7: =(E8-E6)/(F7) -> -0.010253907 | I7: =MOD(360+DEGREES(ATAN2((C8-C6),(D8-D6))),360) -> 219.23116 | J7: =TEXT(ABS(I7/24), "[h]° mm' ss''") -> 219° 13' 52'' | T7: =F7-U8 -> 161.5551
B8: PI1 | C8: 1190661.9 | D8: 837666.26 | E8: 1642 | H8: =IF(K8>0,"Derecha","Izquierda") -> Izquierda | K8: =I9-I7 -> -74.434321 | L8: =(ABS(K8/24)) -> 3.10143 | M8: =C2 -> 40 | N8: =ROUNDUP(((M8)^2)/(127*(0.08+(IF($M8=40,0.23,0.19)))),0) -> 41 | O8: =DEGREES(2*ASIN(($F$2)/(2*N8))) -> 6.9916273 | P8: =TEXT(ABS(O8/24), "[h]° mm' ss''") -> 6° 59' 30'' | Q8: =MROUND(ROUNDDOWN(O8-0.25,2),0.5) -> 6.5 | R8: =(ABS(Q8/24)) -> 0.27083333 | S8: =($F$2)/((SIN(RADIANS(Q8)/2)*2)) -> 44.09732 | U8: =S8*TAN((ABS(RADIANS(K8)))/2) -> 33.492509 | V8: =($F$2*ABS(K8))/(Q8) -> 57.25717 | W8: =+W6+F7-U8 -> 161.5551 | X8: =W8+V8 -> 218.81227
F9: =SQRT((C10-C8)^2+(D10-D8)^2) -> 305.19152 | G9: =(E10-E8)/(F9) -> 0.052426096 | I9: =MOD(360+DEGREES(ATAN2((C10-C8),(D10-D8))),360) -> 144.79684 | J9: =TEXT(ABS(I9/24), "[h]° mm' ss''") -> 144° 47' 49'' | T9: =F9-U10-U8 -> 188.18284
B10: PI2 | C10: 1190412.5 | D10: 837842.2 | E10: 1658 | H10: =IF(K10>0,"Derecha","Izquierda") -> Derecha | K10: =I11-I9 -> 91.144857 | L10: =(ABS(K10/24)) -> 3.7977024 | M10: =SUM(AB10:AP10) -> 50 | N10: =ROUNDUP(((M10)^2)/(127*(0.08+(IF($M10=40,0.23,0.19)))),0) -> 73 | O10: =DEGREES(2*ASIN(($F$2)/(2*N10))) -> 3.925136 | P10: =TEXT(ABS(O10/24), "[h]° mm' ss''") -> 3° 55' 30'' | Q10: =MROUND(ROUNDDOWN(O10-0.25,2),0.5) -> 3.5 | R10: =(ABS(Q10/24)) -> 0.14583333 | S10: =($F$2)/((SIN(RADIANS(Q10)/2)*2)) -> 81.863841 | U10: =S10*TAN((ABS(RADIANS(K10)))/2) -> 83.516169 | V10: =($F$2*ABS(K10))/(Q10) -> 130.20694 | W10: =+X8+F9-U8-U10 -> 406.99512 | X10: =W10+V10 -> 537.20206 | AB10: =IF(AND($M8=$C$2,$F9<=70),$C$2,) -> 0 | AC10: =IF(AND($M8=$C$2,$F9>70,$F9<=250,ABS(K10)<45),$C$2,) -> 0 | AD10: =IF(AND($M8=$C$2,$F9>70,$F9<=250,ABS(K10)>45),$C$2,) -> 0 | AE10: =IF(AND($M8=$C$2,$F9>250,$F9<=400),$AQ$2,) -> 50 | AF10: =IF(AND($M8=$C$2,$F9>400),$AR$2,) -> 0 | AG10: =IF(AND($M8=$AQ$2,$F9<=70),$AQ$2,) -> 0 | AH10: =IF(AND($M8=$AQ$2,$F9>70,$F9<=250,ABS(K10)<45),$AQ$2,) -> 0 | AI10: =IF(AND($M8=$AQ$2,$F9>70,$F9<=250,ABS(K10)>45),$C$2,) -> 0 | AJ10: =IF(AND($M8=$AQ$2,$F9>250,$F9<=400),$AQ$2,) -> 0 | AK10: =IF(AND($M8=$AQ$2,$F9>400),$AR$2,) -> 0 | AL10: =IF(AND($M8=$AR$2,$F9<=70),$AR$2,) -> 0 | AM10: =IF(AND($M8=$AR$2,$F9>70,$F9<=250,ABS(K10)<45),$AR$2,) -> 0 | AN10: =IF(AND($M8=$AR$2,$F9>70,$F9<=250,ABS(K10)>45),$AQ$2,) -> 0 | AO10: =IF(AND($M8=$AR$2,$F9>250,$F9<=400),$AQ$2,) -> 0 | AP10: =IF(AND($M8=$AR$2,$F9>400),$AR$2,) -> 0
F11: =SQRT((C12-C10)^2+(D12-D10)^2) -> 207.35981 | G11: =(E12-E10)/(F11) -> -0.12538592 | I11: =MOD(360+DEGREES(ATAN2((C12-C10),(D12-D10))),360) -> 235.9417 | J11: =TEXT(ABS(I11/24), "[h]° mm' ss''") -> 235° 56' 30'' | T11: =F11-U12-U10 -> 120.68279
B12: PI3 | C12: 1190296.4 | D12: 837670.41 | E12: 1632 | H12: =IF(K12>0,"Derecha","Izquierda") -> Izquierda | K12: =I13-I11 -> -4.4223185 | L12: =(ABS(K12/24)) -> 0.18426327 | M12: =SUM(AB12:AP12) -> 50 | N12: =ROUNDUP(((M12)^2)/(127*(0.08+(IF($M12=40,0.23,0.19)))),0) -> 73 | O12: =DEGREES(2*ASIN(($F$2)/(2*N12))) -> 3.925136 | P12: =TEXT(ABS(O12/24), "[h]° mm' ss''") -> 3° 55' 30'' | Q12: =MROUND(ROUNDDOWN(O12-0.25,2),0.5) -> 3.5 | R12: =(ABS(Q12/24)) -> 0.14583333 | S12: =($F$2)/((SIN(RADIANS(Q12)/2)*2)) -> 81.863841 | U12: =S12*TAN((ABS(RADIANS(K12)))/2) -> 3.1608594 | V12: =($F$2*ABS(K12))/(Q12) -> 6.3175978 | W12: =+X10+F11-U10-U12 -> 657.88484 | X12: =W12+V12 -> 664.20244 | AB12: =IF(AND($M10=$C$2,$F11<=70),$C$2,) -> 0 | AC12: =IF(AND($M10=$C$2,$F11>70,$F11<=250,ABS(K12)<45),$C$2,) -> 0 | AD12: =IF(AND($M10=$C$2,$F11>70,$F11<=250,ABS(K12)>45),$C$2,) -> 0 | AE12: =IF(AND($M10=$C$2,$F11>250,$F11<=400),$AQ$2,) -> 0 | AF12: =IF(AND($M10=$C$2,$F11>400),$AR$2,) -> 0 | AG12: =IF(AND($M10=$AQ$2,$F11<=70),$AQ$2,) -> 0 | AH12: =IF(AND($M10=$AQ$2,$F11>70,$F11<=250,ABS(K12)<45),$AQ$2,) -> 50 | AI12: =IF(AND($M10=$AQ$2,$F11>70,$F11<=250,ABS(K12)>45),$C$2,) -> 0 | AJ12: =IF(AND($M10=$AQ$2,$F11>250,$F11<=400),$AQ$2,) -> 0 | AK12: =IF(AND($M10=$AQ$2,$F11>400),$AR$2,) -> 0 | AL12: =IF(AND($M10=$AR$2,$F11<=70),$AR$2,) -> 0 | AM12: =IF(AND($M10=$AR$2,$F11>70,$F11<=250,ABS(K12)<45),$AR$2,) -> 0 | AN12: =IF(AND($M10=$AR$2,$F11>70,$F11<=250,ABS(K12)>45),$AQ$2,) -> 0 | AO12: =IF(AND($M10=$AR$2,$F11>250,$F11<=400),$AQ$2,) -> 0 | AP12: =IF(AND($M10=$AR$2,$F11>400),$AR$2,) -> 0
F13: =SQRT((C14-C12)^2+(D14-D12)^2) -> 185.86424 | G13: =(E14-E12)/(F13) -> 0.043042169 | I13: =MOD(360+DEGREES(ATAN2((C14-C12),(D14-D12))),360) -> 231.51938 | J13: =TEXT(ABS(I13/24), "[h]° mm' ss''") -> 231° 31' 10'' | T13: =F13-U14-U12 -> 149.80073
B14: PI4 | C14: 1190180.8 | D14: 837524.91 | E14: 1640 | H14: =IF(K14>0,"Derecha","Izquierda") -> Izquierda | K14: =I15-I13 -> -43.792285 | L14: =(ABS(K14/24)) -> 1.8246785 | M14: =SUM(AB14:AP14) -> 50 | N14: =ROUNDUP(((M14)^2)/(127*(0.08+(IF($M14=40,0.23,0.19)))),0) -> 73 | O14: =DEGREES(2*ASIN(($F$2)/(2*N14))) -> 3.925136 | P14: =TEXT(ABS(O14/24), "[h]° mm' ss''") -> 3° 55' 30'' | Q14: =MROUND(ROUNDDOWN(O14-0.25,2),0.5) -> 3.5 | R14: =(ABS(Q14/24)) -> 0.14583333 | S14: =($F$2)/((SIN(RADIANS(Q14)/2)*2)) -> 81.863841 | U14: =S14*TAN((ABS(RADIANS(K14)))/2) -> 32.902651 | V14: =($F$2*ABS(K14))/(Q14) -> 62.560407 | W14: =+X12+F13-U12-U14 -> 814.00317 | X14: =W14+V14 -> 876.56358 | AB14: =IF(AND($M12=$C$2,$F13<=70),$C$2,) -> 0 | AC14: =IF(AND($M12=$C$2,$F13>70,$F13<=250,ABS(K14)<45),$C$2,) -> 0 | AD14: =IF(AND($M12=$C$2,$F13>70,$F13<=250,ABS(K14)>45),$C$2,) -> 0 | AE14: =IF(AND($M12=$C$2,$F13>250,$F13<=400),$AQ$2,) -> 0 | AF14: =IF(AND($M12=$C$2,$F13>400),$AR$2,) -> 0 | AG14: =IF(AND($M12=$AQ$2,$F13<=70),$AQ$2,) -> 0 | AH14: =IF(AND($M12=$AQ$2,$F13>70,$F13<=250,ABS(K14)<45),$AQ$2,) -> 50 | AI14: =IF(AND($M12=$AQ$2,$F13>70,$F13<=250,ABS(K14)>45),$C$2,) -> 0 | AJ14: =IF(AND($M12=$AQ$2,$F13>250,$F13<=400),$AQ$2,) -> 0 | AK14: =IF(AND($M12=$AQ$2,$F13>400),$AR$2,) -> 0 | AL14: =IF(AND($M12=$AR$2,$F13<=70),$AR$2,) -> 0 | AM14: =IF(AND($M12=$AR$2,$F13>70,$F13<=250,ABS(K14)<45),$AR$2,) -> 0 | AN14: =IF(AND($M12=$AR$2,$F13>70,$F13<=250,ABS(K14)>45),$AQ$2,) -> 0 | AO14: =IF(AND($M12=$AR$2,$F13>250,$F13<=400),$AQ$2,) -> 0 | AP14: =IF(AND($M12=$AR$2,$F13>400),$AR$2,) -> 0
F15: =SQRT((C16-C14)^2+(D16-D14)^2) -> 354.97426 | G15: =(E16-E14)/(F15) -> -0.061976324 | I15: =MOD(360+DEGREES(ATAN2((C16-C14),(D16-D14))),360) -> 187.7271 | J15: =TEXT(ABS(I15/24), "[h]° mm' ss''") -> 187° 43' 38'' | T15: =F15-U16-U14 -> 272.64118
B16: PI5 | C16: 1189829 | D16: 837477.18 | E16: 1618 | H16: =IF(K16>0,"Derecha","Izquierda") -> Izquierda | K16: =I17-I15 -> -62.248228 | L16: =(ABS(K16/24)) -> 2.5936762 | M16: =SUM(AB16:AP16) -> 50 | N16: =ROUNDUP(((M16)^2)/(127*(0.08+(IF($M16=40,0.23,0.19)))),0) -> 73 | O16: =DEGREES(2*ASIN(($F$2)/(2*N16))) -> 3.925136 | P16: =TEXT(ABS(O16/24), "[h]° mm' ss''") -> 3° 55' 30'' | Q16: =MROUND(ROUNDDOWN(O16-0.25,2),0.5) -> 3.5 | R16: =(ABS(Q16/24)) -> 0.14583333 | S16: =($F$2)/((SIN(RADIANS(Q16)/2)*2)) -> 81.863841 | U16: =S16*TAN((ABS(RADIANS(K16)))/2) -> 49.43043 | V16: =($F$2*ABS(K16))/(Q16) -> 88.92604 | W16: =+X14+F15-U14-U16 -> 1149.2048 | X16: =W16+V16 -> 1238.1308 | AB16: =IF(AND($M14=$C$2,$F15<=70),$C$2,) -> 0 | AC16: =IF(AND($M14=$C$2,$F15>70,$F15<=250,ABS(K16)<45),$C$2,) -> 0 | AD16: =IF(AND($M14=$C$2,$F15>70,$F15<=250,ABS(K16)>45),$C$2,) -> 0 | AE16: =IF(AND($M14=$C$2,$F15>250,$F15<=400),$AQ$2,) -> 0 | AF16: =IF(AND($M14=$C$2,$F15>400),$AR$2,) -> 0 | AG16: =IF(AND($M14=$AQ$2,$F15<=70),$AQ$2,) -> 0 | AH16: =IF(AND($M14=$AQ$2,$F15>70,$F15<=250,ABS(K16)<45),$AQ$2,) -> 0 | AI16: =IF(AND($M14=$AQ$2,$F15>70,$F15<=250,ABS(K16)>45),$C$2,) -> 0 | AJ16: =IF(AND($M14=$AQ$2,$F15>250,$F15<=400),$AQ$2,) -> 50 | AK16: =IF(AND($M14=$AQ$2,$F15>400),$AR$2,) -> 0 | AL16: =IF(AND($M14=$AR$2,$F15<=70),$AR$2,) -> 0 | AM16: =IF(AND($M14=$AR$2,$F15>70,$F15<=250,ABS(K16)<45),$AR$2,) -> 0 | AN16: =IF(AND($M14=$AR$2,$F15>70,$F15<=250,ABS(K16)>45),$AQ$2,) -> 0 | AO16: =IF(AND($M14=$AR$2,$F15>250,$F15<=400),$AQ$2,) -> 0 | AP16: =IF(AND($M14=$AR$2,$F15>400),$AR$2,) -> 0
F17: =SQRT((C18-C16)^2+(D18-D16)^2) -> 186.87027 | G17: =(E18-E16)/(F17) -> 0.085620896 | I17: =MOD(360+DEGREES(ATAN2((C18-C16),(D18-D16))),360) -> 125.47887 | J17: =TEXT(ABS(I17/24), "[h]° mm' ss''") -> 125° 28' 44'' | T17: =F17-U18-U16 -> 105.3609
B18: PI6 | C18: 1189720.6 | D18: 837629.35 | E18: 1634 | H18: =IF(K18>0,"Derecha","Izquierda") -> Derecha | K18: =I19-I17 -> 42.79618 | L18: =(ABS(K18/24)) -> 1.7831742 | M18: =SUM(AB18:AP18) -> 50 | N18: =ROUNDUP(((M18)^2)/(127*(0.08+(IF($M18=40,0.23,0.19)))),0) -> 73 | O18: =DEGREES(2*ASIN(($F$2)/(2*N18))) -> 3.925136 | P18: =TEXT(ABS(O18/24), "[h]° mm' ss''") -> 3° 55' 30'' | Q18: =MROUND(ROUNDDOWN(O18-0.25,2),0.5) -> 3.5 | R18: =(ABS(Q18/24)) -> 0.14583333 | S18: =($F$2)/((SIN(RADIANS(Q18)/2)*2)) -> 81.863841 | U18: =S18*TAN((ABS(RADIANS(K18)))/2) -> 32.078941 | V18: =($F$2*ABS(K18))/(Q18) -> 61.1374 | W18: =+X16+F17-U16-U18 -> 1343.4917 | X18: =W18+V18 -> 1404.6291 | AB18: =IF(AND($M16=$C$2,$F17<=70),$C$2,) -> 0 | AC18: =IF(AND($M16=$C$2,$F17>70,$F17<=250,ABS(K18)<45),$C$2,) -> 0 | AD18: =IF(AND($M16=$C$2,$F17>70,$F17<=250,ABS(K18)>45),$C$2,) -> 0 | AE18: =IF(AND($M16=$C$2,$F17>250,$F17<=400),$AQ$2,) -> 0 | AF18: =IF(AND($M16=$C$2,$F17>400),$AR$2,) -> 0 | AG18: =IF(AND($M16=$AQ$2,$F17<=70),$AQ$2,) -> 0 | AH18: =IF(AND($M16=$AQ$2,$F17>70,$F17<=250,ABS(K18)<45),$AQ$2,) -> 50 | AI18: =IF(AND($M16=$AQ$2,$F17>70,$F17<=250,ABS(K18)>45),$C$2,) -> 0 | AJ18: =IF(AND($M16=$AQ$2,$F17>250,$F17<=400),$AQ$2,) -> 0 | AK18: =IF(AND($M16=$AQ$2,$F17>400),$AR$2,) -> 0 | AL18: =IF(AND($M16=$AR$2,$F17<=70),$AR$2,) -> 0 | AM18: =IF(AND($M16=$AR$2,$F17>70,$F17<=250,ABS(K18)<45),$AR$2,) -> 0 | AN18: =IF(AND($M16=$AR$2,$F17>70,$F17<=250,ABS(K18)>45),$AQ$2,) -> 0 | AO18: =IF(AND($M16=$AR$2,$F17>250,$F17<=400),$AQ$2,) -> 0 | AP18: =IF(AND($M16=$AR$2,$F17>400),$AR$2,) -> 0
F19: =SQRT((C20-C18)^2+(D20-D18)^2) -> 152.18953 | G19: =(E20-E18)/(F19) -> 0.039424527 | I19: =MOD(360+DEGREES(ATAN2((C20-C18),(D20-D18))),360) -> 168.27505 | J19: =TEXT(ABS(I19/24), "[h]° mm' ss''") -> 168° 16' 30'' | T19: =F19-U20-U18 -> 114.69935
B20: PI7 | C20: 1189571.5 | D20: 837660.28 | E20: 1640 | H20: =IF(K20>0,"Derecha","Izquierda") -> Derecha | K20: =I21-I19 -> 7.563549 | L20: =(ABS(K20/24)) -> 0.31514787 | M20: =SUM(AB20:AP20) -> 50 | N20: =ROUNDUP(((M20)^2)/(127*(0.08+(IF($M20=40,0.23,0.19)))),0) -> 73 | O20: =DEGREES(2*ASIN(($F$2)/(2*N20))) -> 3.925136 | P20: =TEXT(ABS(O20/24), "[h]° mm' ss''") -> 3° 55' 30'' | Q20: =MROUND(ROUNDDOWN(O20-0.25,2),0.5) -> 3.5 | R20: =(ABS(Q20/24)) -> 0.14583333 | S20: =($F$2)/((SIN(RADIANS(Q20)/2)*2)) -> 81.863841 | U20: =S20*TAN((ABS(RADIANS(K20)))/2) -> 5.4112355 | V20: =($F$2*ABS(K20))/(Q20) -> 10.80507 | W20: =+X18+F19-U18-U20 -> 1519.3284 | X20: =W20+V20 -> 1530.1335 | AB20: =IF(AND($M18=$C$2,$F19<=70),$C$2,) -> 0 | AC20: =IF(AND($M18=$C$2,$F19>70,$F19<=250,ABS(K20)<45),$C$2,) -> 0 | AD20: =IF(AND($M18=$C$2,$F19>70,$F19<=250,ABS(K20)>45),$C$2,) -> 0 | AE20: =IF(AND($M18=$C$2,$F19>250,$F19<=400),$AQ$2,) -> 0 | AF20: =IF(AND($M18=$C$2,$F19>400),$AR$2,) -> 0 | AG20: =IF(AND($M18=$AQ$2,$F19<=70),$AQ$2,) -> 0 | AH20: =IF(AND($M18=$AQ$2,$F19>70,$F19<=250,ABS(K20)<45),$AQ$2,) -> 50 | AI20: =IF(AND($M18=$AQ$2,$F19>70,$F19<=250,ABS(K20)>45),$C$2,) -> 0 | AJ20: =IF(AND($M18=$AQ$2,$F19>250,$F19<=400),$AQ$2,) -> 0 | AK20: =IF(AND($M18=$AQ$2,$F19>400),$AR$2,) -> 0 | AL20: =IF(AND($M18=$AR$2,$F19<=70),$AR$2,) -> 0 | AM20: =IF(AND($M18=$AR$2,$F19>70,$F19<=250,ABS(K20)<45),$AR$2,) -> 0 | AN20: =IF(AND($M18=$AR$2,$F19>70,$F19<=250,ABS(K20)>45),$AQ$2,) -> 0 | AO20: =IF(AND($M18=$AR$2,$F19>250,$F19<=400),$AQ$2,) -> 0 | AP20: =IF(AND($M18=$AR$2,$F19>400),$AR$2,) -> 0
F21: =SQRT((C22-C20)^2+(D22-D20)^2) -> 156.95981 | G21: =(E22-E20)/(F21) -> 0.063710576 | I21: =MOD(360+DEGREES(ATAN2((C22-C20),(D22-D20))),360) -> 175.8386 | J21: =TEXT(ABS(I21/24), "[h]° mm' ss''") -> 175° 50' 19'' | T21: =F21-U22-U20 -> 141.0434
B22: PI8 | C22: 1189415 | D22: 837671.67 | E22: 1650 | H22: =IF(K22>0,"Derecha","Izquierda") -> Derecha | K22: =I23-I21 -> 14.625036 | L22: =(ABS(K22/24)) -> 0.60937651 | M22: 50 | N22: =ROUNDUP(((M22)^2)/(127*(0.08+(IF($M22=40,0.23,0.19)))),0) -> 73 | O22: =DEGREES(2*ASIN(($F$2)/(2*N22))) -> 3.925136 | P22: =TEXT(ABS(O22/24), "[h]° mm' ss''") -> 3° 55' 30'' | Q22: =MROUND(ROUNDDOWN(O22-0.25,2),0.5) -> 3.5 | R22: =(ABS(Q22/24)) -> 0.14583333 | S22: =($F$2)/((SIN(RADIANS(Q22)/2)*2)) -> 81.863841 | U22: =S22*TAN((ABS(RADIANS(K22)))/2) -> 10.50518 | V22: =($F$2*ABS(K22))/(Q22) -> 20.892909 | W22: =+X20+F21-U20-U22 -> 1671.1769 | X22: =W22+V22 -> 1692.0698
F23: =SQRT((C24-C22)^2+(D24-D22)^2) -> 166.66355 | G23: =(E24-E22)/(F23) -> 0.012000224 | I23: =MOD(360+DEGREES(ATAN2((C24-C22),(D24-D22))),360) -> 190.46363 | J23: =TEXT(ABS(I23/24), "[h]° mm' ss''") -> 190° 27' 49'' | T23: =F23-U24-U22 -> 156.15837
B24: P3 (Final) | C24: 1189251.1 | D24: 837641.4 | E24: 1652 | W24: =X22+T23 -> 1848.2282 | AB24: =IF(AND($M20=$C$2,$F21<=70),$C$2,) -> 0 | AC24: =IF(AND($M20=$C$2,$F21>70,$F21<=250,ABS(K24)<45),$C$2,) -> 0 | AD24: =IF(AND($M20=$C$2,$F21>70,$F21<=250,ABS(K24)>45),$C$2,) -> 0 | AE24: =IF(AND($M20=$C$2,$F21>250,$F21<=400),$AQ$2,) -> 0 | AF24: =IF(AND($M20=$C$2,$F21>400),$AR$2,) -> 0 | AG24: =IF(AND($M20=$AQ$2,$F21<=70),$AQ$2,) -> 0 | AH24: =IF(AND($M20=$AQ$2,$F21>70,$F21<=250,ABS(K24)<45),$AQ$2,) -> 50 | AI24: =IF(AND($M20=$AQ$2,$F21>70,$F21<=250,ABS(K24)>45),$C$2,) -> 0 | AJ24: =IF(AND($M20=$AQ$2,$F21>250,$F21<=400),$AQ$2,) -> 0 | AK24: =IF(AND($M20=$AQ$2,$F21>400),$AR$2,) -> 0 | AL24: =IF(AND($M20=$AR$2,$F21<=70),$AR$2,) -> 0 | AM24: =IF(AND($M20=$AR$2,$F21>70,$F21<=250,ABS(K24)<45),$AR$2,) -> 0 | AN24: =IF(AND($M20=$AR$2,$F21>70,$F21<=250,ABS(K24)>45),$AQ$2,) -> 0 | AO24: =IF(AND($M20=$AR$2,$F21>250,$F21<=400),$AQ$2,) -> 0 | AP24: =IF(AND($M20=$AR$2,$F21>400),$AR$2,) -> 0
B25: P2 | C25: 1190116.3 | D25: 837516.17 | W25: =X14+32.132 -> 908.69558

Sheet CARTERA HZ
B2: VTR [km/h] | C2: 40 | E2: c [m] | F2: 5
B4: PUNTO | C4: COORDENADAS | D4: COORDENADAS | E4: PENDIENTE [%] | F4: DISTANCIA [m] | G4: ACIMUT [° ' ''] | H4: DEFLEXION - Δ | I4: DEFLEXION - Δ | J4: VCH [km/h] | K4: Rmin [m] | L4: Gc max [° ' ''] | M4: Gredondo [° ' ''] | N4: Rmin Definitivo [m] | O4: DISTDefinitiva [m] | P4: T [m] | Q4: Lc [m] | R4: ABSCISAS
C5: NORTE | D5: ESTE | H5: [° ' ''] | I5: SENTIDO | R5: PC | S5: PT
B6: P1 (Inicial) | C6: 1190813 | D6: 837789.62 | R6: 0
E7: -0.010253907 | F7: 195.04761 | G7: 219° 13' 52'' | O7: 161.5551
B8: PI1 | C8: 1190661.9 | D8: 837666.26 | H8: 3.10143 | I8: Izquierda | J8: 40 | K8: 41 | L8: 6° 59' 30'' | M8: 0.27083333 | N8: 44.09732 | P8: 33.492509 | Q8: 57.25717 | R8: 161.5551 | S8: 218.81227
E9: 0.052426096 | F9: 305.19152 | G9: 144° 47' 49'' | O9: 188.18284
B10: PI2 | C10: 1190412.5 | D10: 837842.2 | H10: 3.7977024 | I10: Derecha | J10: 50 | K10: 73 | L10: 3° 55' 30'' | M10: 0.14583333 | N10: 81.863841 | P10: 83.516169 | Q10: 130.20694 | R10: 406.99512 | S10: 537.20206
E11: -0.12538592 | F11: 207.35981 | G11: 235° 56' 30'' | O11: 120.68279
B12: PI3 | C12: 1190296.4 | D12: 837670.41 | H12: 0.18426327 | I12: Izquierda | J12: 50 | K12: 73 | L12: 3° 55' 30'' | M12: 0.14583333 | N12: 81.863841 | P12: 3.1608594 | Q12: 6.3175978 | R12: 657.88484 | S12: 664.20244
E13: 0.043042169 | F13: 185.86424 | G13: 231° 31' 10'' | O13: 149.80073
B14: PI4 | C14: 1190180.8 | D14: 837524.91 | H14: 1.8246785 | I14: Izquierda | J14: 50 | K14: 73 | L14: 3° 55' 30'' | M14: 0.14583333 | N14: 81.863841 | P14: 32.902651 | Q14: 62.560407 | R14: 814.00317 | S14: 876.56358
E15: -0.061976324 | F15: 354.97426 | G15: 187° 43' 38'' | O15: 272.64118
B16: PI5 | C16: 1189829 | D16: 837477.18 | H16: 2.5936762 | I16: Izquierda | J16: 50 | K16: 73 | L16: 3° 55' 30'' | M16: 0.14583333 | N16: 81.863841 | P16: 49.43043 | Q16: 88.92604 | R16: 1149.2048 | S16: 1238.1308
E17: 0.085620896 | F17: 186.87027 | G17: 125° 28' 44'' | O17: 105.3609
B18: PI6 | C18: 1189720.6 | D18: 837629.35 | H18: 1.7831742 | I18: Derecha | J18: 50 | K18: 73 | L18: 3° 55' 30'' | M18: 0.14583333 | N18: 81.863841 | P18: 32.078941 | Q18: 61.1374 | R18: 1343.4917 | S18: 1404.6291
E19: 0.039424527 | F19: 152.18953 | G19: 168° 16' 30'' | O19: 114.69935
B20: PI7 | C20: 1189571.5 | D20: 837660.28 | H20: 0.31514787 | I20: Derecha | J20: 50 | K20: 73 | L20: 3° 55' 30'' | M20: 0.14583333 | N20: 81.863841 | P20: 5.4112355 | Q20: 10.80507 | R20: 1519.3284 | S20: 1530.1335
E21: 0.063710576 | F21: 156.95981 | G21: 175° 50' 19'' | O21: 141.0434
B22: PI8 | C22: 1189415 | D22: 837671.67 | H22: 0.60937651 | I22: Derecha | J22: 50 | K22: 73 | L22: 3° 55' 30'' | M22: 0.14583333 | N22: 81.863841 | P22: 10.50518 | Q22: 20.892909 | R22: 1671.1769 | S22: 1692.0698
E23: 0.012000224 | F23: 166.66355 | G23: 190° 27' 49'' | O23: 156.15837
B24: P3 (Final) | C24: 1189251.1 | D24: 837641.4 | R24: 1848.2282
B25: P2 | C25: 1190116.3 | D25: 837516.17 | R25: 908.69558

Sheet PERALTE
B2: PUNTO | C2: EReal [m] | D2: EIdeal [m] | E2: Lc [m] | F2: VCH [km/h] | G2: Δs_min [m] | H2: Δs_max (%) | I2: LR_min [m] | J2: LR_max [m] | K2: N_min [m] | L2: N_max [m] | M2: N_def [m] | N2: LR_def [m] | O2: % LR en recta | P2: DbReal [m] | Q2: ABSCISAS DE ENTRADA | V2: ABSCISAS DE CURVA | X2: ABSCISAS DE SALIDA
Q3: Fin Db | R3: Aplanam. | S3: e = b | T3: x = 4% | U3: emáx | V3: PC | W3: PT | X3: emáx | Y3: x = 4% | Z3: e = b | AA3: Aplanam. | AB3: Inicio Db
B4: P1 (Inicial) | V4: 0 | W4: 0
C5: =AH!T7 -> 161.5551 | D5: =N6*O6+M6+10 -> 46.458333 | P5: =C5-N6*O6-N4*O4-M6-M4 -> 125.09677
B6: PI1 | E6: =AH!V8 -> 57.25717 | F6: =AH!M8 -> 40 | G6: =$C$32*0.1 -> 0.35 | H6: =IF(F6=40,0.96,IF(F6=50,0.77,IF(F6=60,0.6,))) -> 0.96 | I6: =($C$34*$C$32)/(H6) -> 29.166667 | J6: =($C$34*$C$32)/(G6) -> 80 | K6: =($C$33*I6)/($C$34) -> 7.2916667 | L6: =($C$33*J6)/($C$34) -> 20 | M6: =K6 -> 7.2916667 | N6: =I6 -> 29.166667 | O6: 1 | Q6: =W4+P5 -> 125.09677 | R6: =Q6+M6 -> 132.38844 | S6: =R6+M6 -> 139.6801 | T6: =R6+(4*N6)/(8) -> 146.97177 | U6: =R6+N6 -> 161.5551 | V6: =AH!W8 -> 161.5551 | W6: =AH!X8 -> 218.81227 | X6: =U6+E6 -> 218.81227 | Y6: =X6+(4*N6)/(8) -> 233.39561 | Z6: =X6+N6-M6 -> 240.68727 | AA6: =X6+N6 -> 247.97894 | AB6: =AA6+M6 -> 255.27061
C7: =AH!T9 -> 188.18284 | D7: =N8*O8+M8+10+M6+N6*O6 -> 91.912879 | P7: =C7-N8*O8-N6*O6-M8-M6 -> 106.26997
B8: PI2 | E8: =AH!V10 -> 130.20694 | F8: =AH!M10 -> 50 | G8: =$C$32*0.1 -> 0.35 | H8: =IF(F8=40,0.96,IF(F8=50,0.77,IF(F8=60,0.6,))) -> 0.77 | I8: =($C$34*$C$32)/(H8) -> 36.363636 | J8: =($C$34*$C$32)/(G8) -> 80 | K8: =($C$33*I8)/($C$34) -> 9.0909091 | L8: =($C$33*J8)/($C$34) -> 20 | M8: =K8 -> 9.0909091 | N8: =I8 -> 36.363636 | O8: 1 | Q8: =W6+P7+N8+M8 -> 370.53678 | R8: =Q8+M8 -> 379.62769 | S8: =R8+M8 -> 388.7186 | T8: =R8+(4*N8)/(8) -> 397.80951 | U8: =R8+N8 -> 415.99133 | V8: =AH!W10 -> 406.99512 | W8: =AH!X10 -> 537.20206 | X8: =U8+E8 -> 546.19827 | Y8: =X8+(4*N8)/(8) -> 564.38009 | Z8: =X8+N8-M8 -> 573.471 | AA8: =X8+N8 -> 582.56191 | AB8: =AA8+M8 -> 591.65281
C9: =AH!T11 -> 120.68279 | D9: =N10*O10+M10+10+M8+N8*O8 -> 100.90909 | P9: =C9-N10*O10-N8*O8-M10-M8 -> 29.773695
B10: PI3 | E10: =AH!V12 -> 6.3175978 | F10: =AH!M12 -> 50 | G10: =$C$32*0.1 -> 0.35 | H10: =IF(F10=40,0.96,IF(F10=50,0.77,IF(F10=60,0.6,))) -> 0.77 | I10: =($C$34*$C$32)/(H10) -> 36.363636 | J10: =($C$34*$C$32)/(G10) -> 80 | K10: =($C$33*I10)/($C$34) -> 9.0909091 | L10: =($C$33*J10)/($C$34) -> 20 | M10: =K10 -> 9.0909091 | N10: =I10 -> 36.363636 | O10: 1 | Q10: =W8+P9+N10+M10 -> 612.4303 | R10: =Q10+M10 -> 621.52121 | S10: =R10+M10 -> 630.61211 | T10: =R10+(4*N10)/(8) -> 639.70302 | U10: =R10+N10 -> 657.88484 | V10: =AH!W12 -> 657.88484 | W10: =AH!X12 -> 664.20244 | X10: =U10+E10 -> 664.20244 | Y10: =X10+(4*N10)/(8) -> 682.38426 | Z10: =X10+N10-M10 -> 691.47517 | AA10: =X10+N10 -> 700.56608 | AB10: =AA10+M10 -> 709.65699
C11: =AH!T13 -> 149.80073 | D11: =N12*O12+M12+10+M10+N10*O10 -> 100.90909 | P11: =C11-N12*O12-N10*O10-M12-M10 -> 58.891638
B12: PI4 | E12: =AH!V14 -> 62.560407 | F12: =AH!M14 -> 50 | G12: =$C$32*0.1 -> 0.35 | H12: =IF(F12=40,0.96,IF(F12=50,0.77,IF(F12=60,0.6,))) -> 0.77 | I12: =($C$34*$C$32)/(H12) -> 36.363636 | J12: =($C$34*$C$32)/(G12) -> 80 | K12: =($C$33*I12)/($C$34) -> 9.0909091 | L12: =($C$33*J12)/($C$34) -> 20 | M12: =K12 -> 9.0909091 | N12: =I12 -> 36.363636 | O12: 1 | Q12: =W10+P11+N12+M12 -> 768.54862 | R12: =Q12+M12 -> 777.63953 | S12: =R12+M12 -> 786.73044 | T12: =R12+(4*N12)/(8) -> 795.82135 | U12: =R12+N12 -> 814.00317 | V12: =AH!W14 -> 814.00317 | W12: =AH!X14 -> 876.56358 | X12: =U12+E12 -> 876.56358 | Y12: =X12+(4*N12)/(8) -> 894.74539 | Z12: =X12+N12-M12 -> 903.8363 | AA12: =X12+N12 -> 912.92721 | AB12: =AA12+M12 -> 922.01812
C13: =AH!T15 -> 272.64118 | D13: =N14*O14+M14+10+M12+N12*O12 -> 100.90909 | P13: =C13-N14*O14-N12*O12-M14-M12 -> 181.73209
B14: PI5 | E14: =AH!V16 -> 88.92604 | F14: =AH!M16 -> 50 | G14: =$C$32*0.1 -> 0.35 | H14: =IF(F14=40,0.96,IF(F14=50,0.77,IF(F14=60,0.6,))) -> 0.77 | I14: =($C$34*$C$32)/(H14) -> 36.363636 | J14: =($C$34*$C$32)/(G14) -> 80 | K14: =($C$33*I14)/($C$34) -> 9.0909091 | L14: =($C$33*J14)/($C$34) -> 20 | M14: =K14 -> 9.0909091 | N14: =I14 -> 36.363636 | O14: 1 | Q14: =W12+P13+N14+M14 -> 1103.7502 | R14: =Q14+M14 -> 1112.8411 | S14: =R14+M14 -> 1121.932 | T14: =R14+(4*N14)/(8) -> 1131.0229 | U14: =R14+N14 -> 1149.2048 | V14: =AH!W16 -> 1149.2048 | W14: =AH!X16 -> 1238.1308 | X14: =U14+E14 -> 1238.1308 | Y14: =X14+(4*N14)/(8) -> 1256.3126 | Z14: =X14+N14-M14 -> 1265.4035 | AA14: =X14+N14 -> 1274.4944 | AB14: =AA14+M14 -> 1283.5853
C15: =AH!T17 -> 105.3609 | D15: =N16*O16+M16+10+M14+N14*O14 -> 100.90909 | P15: =C15-N16*O16-N14*O14-M16-M14 -> 14.451809
B16: PI6 | E16: =AH!V18 -> 61.1374 | F16: =AH!M18 -> 50 | G16: =$C$32*0.1 -> 0.35 | H16: =IF(F16=40,0.96,IF(F16=50,0.77,IF(F16=60,0.6,))) -> 0.77 | I16: =($C$34*$C$32)/(H16) -> 36.363636 | J16: =($C$34*$C$32)/(G16) -> 80 | K16: =($C$33*I16)/($C$34) -> 9.0909091 | L16: =($C$33*J16)/($C$34) -> 20 | M16: =K16 -> 9.0909091 | N16: =I16 -> 36.363636 | O16: 1 | Q16: =W14+P15+N16+M16 -> 1298.0372 | R16: =Q16+M16 -> 1307.1281 | S16: =R16+M16 -> 1316.219 | T16: =R16+(4*N16)/(8) -> 1325.3099 | U16: =R16+N16 -> 1343.4917 | V16: =AH!W18 -> 1343.4917 | W16: =AH!X18 -> 1404.6291 | X16: =U16+E16 -> 1404.6291 | Y16: =X16+(4*N16)/(8) -> 1422.8109 | Z16: =X16+N16-M16 -> 1431.9018 | AA16: =X16+N16 -> 1440.9927 | AB16: =AA16+M16 -> 1450.0836
C17: =AH!T19 -> 114.69935 | D17: =N18*O18+M18+10+M16+N16*O16 -> 100.90909 | P17: =C17-N18*O18-N16*O16-M18-M16 -> 23.790258
B18: PI7 | E18: =AH!V20 -> 10.80507 | F18: =AH!M20 -> 50 | G18: =$C$32*0.1 -> 0.35 | H18: =IF(F18=40,0.96,IF(F18=50,0.77,IF(F18=60,0.6,))) -> 0.77 | I18: =($C$34*$C$32)/(H18) -> 36.363636 | J18: =($C$34*$C$32)/(G18) -> 80 | K18: =($C$33*I18)/($C$34) -> 9.0909091 | L18: =($C$33*J18)/($C$34) -> 20 | M18: =K18 -> 9.0909091 | N18: =I18 -> 36.363636 | O18: 1 | Q18: =W16+P17+N18+M18 -> 1473.8739 | R18: =Q18+M18 -> 1482.9648 | S18: =R18+M18 -> 1492.0557 | T18: =R18+(4*N18)/(8) -> 1501.1466 | U18: =R18+N18 -> 1519.3284 | V18: =AH!W20 -> 1519.3284 | W18: =AH!X20 -> 1530.1335 | X18: =U18+E18 -> 1530.1335 | Y18: =X18+(4*N18)/(8) -> 1548.3153 | Z18: =X18+N18-M18 -> 1557.4062 | AA18: =X18+N18 -> 1566.4972 | AB18: =AA18+M18 -> 1575.5881
C19: =AH!T21 -> 141.0434 | D19: =N20*O20+M20+10+M18+N18*O18 -> 100.90909 | P19: =C19-N20*O20-N18*O18-M20-M18 -> 50.134305
B20: PI8 | E20: =AH!V22 -> 20.892909 | F20: 50 | G20: 0.35 | H20: 0.77 | I20: 36.363636 | J20: 80 | K20: 9.0909091 | L20: 20 | M20: 9.0909091 | N20: 36.363636 | O20: 1 | Q20: =W18+P19+N20+M20 -> 1625.7224 | R20: =Q20+M20 -> 1634.8133 | S20: =R20+M20 -> 1643.9042 | T20: =R20+(4*N20)/(8) -> 1652.9951 | U20: =R20+N20 -> 1671.1769 | V20: =AH!W22 -> 1671.1769 | W20: =AH!X22 -> 1692.0698 | X20: =U20+E20 -> 1692.0698 | Y20: =X20+(4*N20)/(8) -> 1710.2516 | Z20: =X20+N20-M20 -> 1719.3425 | AA20: =X20+N20 -> 1728.4335 | AB20: =AA20+M20 -> 1737.5244
C21: =AH!T23 -> 156.15837 | D21: =N22*O22+M22+10+M20+N20*O20 -> 55.454545 | P21: =C21-N22*O22-N20*O20-M22-M20 -> 110.70383
B22: P3 (Final) | V22: =AH!W24 -> 1848.2282
B23: P2 | V23: =AH!W25 -> 908.69558
B32: Ancho | C32: 3.5
B33: Bombeo | C33: 2
B34: Peralte | C34: 8

Sheet Grafica_Peraltes
A1: PI | B1: PUTNO | C1: ABSCISA | D1: ei | E1: ed
A2: P1 | C2: 0 | D2: -0.02 | E2: -0.02
A3: 1 | B3: A | C3: 125.09677 | D3: -0.02 | E3: -0.02 | G3: A | H3: BOMBEO NORMAL
B4: B | C4: 132.38844 | D4: -0.02 | E4: 0 | F4: IZ | G4: B | H4: APLANAMIENTO
B5: C | C5: 139.6801 | D5: -0.02 | E5: 0.02 | G5: C | H5: E=BOMBEO
B6: D | C6: 161.5551 | D6: -0.08 | E6: 0.08 | G6: D | H6: PERALTE MAXIMO
B7: D' | C7: 218.81227 | D7: -0.08 | E7: 0.08
B8: C' | C8: 240.68727 | D8: -0.02 | E8: 0.02
B9: B' | C9: 247.97894 | D9: -0.02 | E9: 0
B10: A' | C10: 255.27061 | D10: -0.02 | E10: -0.02
A11: 2 | B11: A | C11: 370.53678 | D11: -0.02 | E11: -0.02
B12: B | C12: 379.62769 | D12: 0 | E12: -0.02
B13: C | C13: 388.7186 | D13: 0.02 | E13: -0.02 | F13: DER
B14: D | C14: 415.99133 | D14: 0.08 | E14: -0.08
B15: D' | C15: 546.19827 | D15: 0.08 | E15: -0.08
B16: C' | C16: 573.471 | D16: 0.02 | E16: -0.02
B17: B' | C17: 582.56191 | D17: 0 | E17: -0.02
B18: A' | C18: 591.65281 | D18: -0.02 | E18: -0.02
A19: 3 | B19: A | C19: 612.4303 | D19: -0.02 | E19: -0.02
B20: B | C20: 621.52121 | D20: -0.02 | E20: 0
B21: C | C21: 630.61211 | D21: -0.02 | E21: 0.02
B22: D | C22: 657.88484 | D22: -0.08 | E22: 0.08
B23: D' | C23: 664.20244 | D23: -0.08 | E23: 0.08
B24: C' | C24: 691.47517 | D24: -0.02 | E24: 0.02
B25: B' | C25: 700.56608 | D25: -0.02 | E25: 0
B26: A' | C26: 709.65699 | D26: -0.02 | E26: -0.02
A27: 4 | B27: A | C27: 768.54862 | D27: -0.02 | E27: -0.02
B28: B | C28: 777.63953 | D28: -0.02 | E28: 0
B29: C | C29: 786.73044 | D29: -0.02 | E29: 0.02
B30: D | C30: 814.00317 | D30: -0.08 | E30: 0.08
B31: D' | C31: 876.56358 | D31: -0.08 | E31: 0.08
B32: C' | C32: 903.8363 | D32: -0.02 | E32: 0.02
B33: B' | C33: 912.92721 | D33: -0.02 | E33: 0
B34: A' | C34: 922.01812 | D34: -0.02 | E34: -0.02
A35: 5 | B35: A | C35: 1103.7502 | D35: -0.02 | E35: -0.02
B36: B | C36: 1112.8411 | D36: -0.02 | E36: 0
B37: C | C37: 1121.932 | D37: -0.02 | E37: 0.02
B38: D | C38: 1149.2048 | D38: -0.08 | E38: 0.08
B39: D' | C39: 1238.1308 | D39: -0.08 | E39: 0.08
B40: C' | C40: 1265.4035 | D40: -0.02 | E40: 0.02
...

Sheet AV
B2: TANGENTE | C2: PENDIENTE [%] | D2: LONGITUD [m] | E2: VTV [km/h] | F2: Lmin [m] | G2: Lcritico [m] | H2: PIV | I2: VCV [km/h] | J2: A [%] | K2: LCV min [m] | L2: LCV max [m] | M2: Lcv [m] | N2: LV1 [m] | O2: LV2 [m] | P2: EXTERNA (m) | Q2: TIPO DE CURVA | S2: ABSCISAS | V2: COTAS
Q3: CONCAVIDAD | R3: SIMETRÍA | S3: PCV | T3: PIV | U3: PTV | V3: PCV | W3: PIV | X3: PTV
H4: P1 (Inicial) | T4: 0 | W4: 1644 | AI4: Puentes | AJ4: Pendiente | AK4: Abscisa inicio | AL4: Abscisa final | AM4: Cota inicial | AN4: Cota final | AO4: Longitud(m) | AP4: Galibo(m)
B5: 1 | C5: 3.142 | D5: 301.861 | E5: 40 | F5: =IF(E5=40,80,) -> 80 | G5: 1800 | AI5: 1 | AJ5: 0.07241 | AK5: =T20+48.515 -> 957.21058 | AL5: =AK5+AO5 -> 999.19158 | AM5: 1617.1548 | AN5: 1614.6927 | AO5: 41.981 | AP5: 12.3
H6: PIV1 | I6: 50 | J6: =C7-C5 -> -10.916 | K6: 95 | L6: =J6*50*-1 -> 545.8 | M6: =ROUNDUP(MIN(K6:L6),0) -> 95 | N6: =M6/2 -> 47.5 | O6: =M6-N6 -> 47.5 | P6: =(N6*O6*J6)/(200*M6) -> -1.296275 | Q6: =IF(J6<0,"CONVEXA","CONCAVA") -> CONVEXA | R6: =IF(N6=O6,"SIMETRICA","ASIMETRICA") -> SIMETRICA | S6: =T6-N6 -> 240.479 | T6: 287.979 | U6: =T6+O6 -> 335.479 | V6: =W6-N6*(C5/100) -> 1651.5564 | W6: 1653.0488 | X6: =W6+O6*(C7/100) -> 1649.3562
B7: 2 | C7: -7.774 | D7: 260.805 | E7: 50 | F7: 140 | G7: 295
H8: PIV2 | I8: 50 | J8: =C9-C7 -> 4.774 | K8: 50 | L8: =J8*50 -> 238.7 | M8: =ROUNDUP(MIN(K8:L8),0) -> 50 | N8: =M8/2 -> 25 | O8: =M8-N8 -> 25 | P8: =(N8*O8*J8)/(200*M8) -> 0.298375 | Q8: =IF(J8<0,"CONVEXA","CONCAVA") -> CONCAVA | R8: =IF(N8=O8,"SIMETRICA","ASIMETRICA") -> SIMETRICA | S8: =T8-N8 -> 468.882 | T8: 493.882 | U8: =T8+O8 -> 518.882 | V8: =W8-N8*(C7/100) -> 1638.985 | W8: 1637.0415 | X8: =W8+O8*(C9/100) -> 1636.2915
B9: 3 | C9: -3 | D9: 302.769 | E9: 50 | F9: 140 | G9: 1800 | AI9: Cortes | AJ9: Altura(m) | AK9: Abscisa inicio | AL9: Abscisa final | AM9: Cota inicial | AN9: Cota final | AO9: Longitud(m)
H10: PIV3 | I10: 50 | J10: =C11-C9 -> -4.241 | K10: 30 | L10: =J10*50*-1 -> 212.05 | M10: =ROUNDUP(MIN(K10:L10),0) -> 30 | N10: =M10/2 -> 15 | O10: =M10-N10 -> 15 | P10: =(N10*O10*J10)/(200*M10) -> -0.1590375 | Q10: =IF(J10<0,"CONVEXA","CONCAVA") -> CONVEXA | R10: =IF(N10=O10,"SIMETRICA","ASIMETRICA") -> SIMETRICA | S10: =T10-N10 -> 768.882 | T10: 783.882 | U10: =T10+O10 -> 798.882 | V10: =W10-N10*(C9/100) -> 1628.7915 | W10: 1628.3415 | X10: =W10+O10*(C11/100) -> 1627.2553 | AI10: 1 | AJ10: 5.548 | AK10: 0 | AL10: 154.165 | AM10: 1644 | AN10: 1648.621 | AO10: =AL10-AK10 -> 154.165
B11: 4 | C11: -7.241 | D11: 319.91 | E11: 50 | F11: 140 | G11: 330 | AI11: 2 | AJ11: 2.312 | AK11: 216.204 | AL11: 260.314 | AM11: 1650.481 | AN11: 1651.703 | AO11: =AL11-AK11 -> 44.11
H12: PIV4 | I12: 50 | J12: =C13-C11 -> 15.441 | K12: 160 | L12: =J12*50 -> 772.05 | M12: =ROUNDUP(MIN(K12:L12),0) -> 160 | N12: =M12/2 -> 80 | O12: =M12-N12 -> 80 | P12: =(N12*O12*J12)/(200*M12) -> 3.0882 | Q12: =IF(J12<0,"CONVEXA","CONCAVA") -> CONCAVA | R12: =IF(N12=O12,"SIMETRICA","ASIMETRICA") -> SIMETRICA | S12: =T12-N12 -> 963 | T12: 1043 | U12: =T12+O12 -> 1123 | V12: =W12-N12*(C11/100) -> 1615.3726 | W12: 1609.5798 | X12: =W12+O12*(C13/100) -> 1616.1398 | AI12: 3 | AJ12: 14.154 | AK12: =U6+55.879 -> 391.358 | AL12: =664.202-88.578 -> 575.624 | AM12: 1645.765 | AN12: 1634.477 | AO12: =AL12-AK12 -> 184.266
B13: 5 | C13: 8.2 | D13: 280.391 | E13: 50 | F13: 140 | G13: 282 | AI13: 4 | AJ13: 21.11 | AK13: =68.647+664.2024 -> 732.8494 | AL13: 899.08558 | AM13: 1629.952 | AN13: 1620 | AO13: =AL13-AK13 -> 166.23618
H14: PIV5 | I14: 50 | J14: =C15-C13 -> -5.4 | K14: 30 | L14: =J14*50*-1 -> 270 | M14: =ROUNDUP(MIN(K14:L14),0) -> 30 | N14: =M14/2 -> 15 | O14: =M14-N14 -> 15 | P14: =(N14*O14*J14)/(200*M14) -> -0.2025 | Q14: =IF(J14<0,"CONVEXA","CONCAVA") -> CONVEXA | R14: =IF(N14=O14,"SIMETRICA","ASIMETRICA") -> SIMETRICA | S14: =T14-N14 -> 1244.817 | T14: 1259.817 | U14: =T14+O14 -> 1274.817 | V14: =W14-N14*(C13/100) -> 1626.1288 | W14: 1627.3588 | X14: =W14+O14*(C15/100) -> 1627.7788 | AI14: 5 | AJ14: 4.332 | AK14: =AL14-AO14 -> 1532.917 | AL14: =1761.282-50.798 -> 1710.484 | AM14: 1611.01 | AN14: 1622.269 | AO14: 177.567
B15: 6 | C15: 2.8 | D15: 290.769 | E15: 50 | F15: 140 | G15: 1800
H16: PIV6 | I16: 50 | J16: =C17-C15 -> 2.648 | K16: 40 | L16: =J16*50 -> 132.4 | M16: =ROUNDUP(MIN(K16:L16),0) -> 40 | N16: =M16/2 -> 20 | O16: =M16-N16 -> 20 | P16: =(N16*O16*J16)/(200*M16) -> 0.1324 | Q16: =IF(J16<0,"CONVEXA","CONCAVA") -> CONCAVA | R16: =IF(N16=O16,"SIMETRICA","ASIMETRICA") -> SIMETRICA | S16: =T16-N16 -> 1519.817 | T16: 1539.817 | U16: =T16+O16 -> 1559.817 | V16: =W16-N16*(C15/100) -> 1634.6388 | W16: 1635.1988 | X16: =W16+O16*(C17/100) -> 1636.2884
B17: 7 | C17: 5.448 | D17: 351.206 | E17: 50 | F17: 140 | G17: 450
H19: P3 (Final) | S19: 1848.2282 | T19: 1848.2282 | U19: 1848.2282 | W19: 1652
H20: P2 | T20: ='CARTERA HZ'!R25 -> 908.69558 | W20: 1620
B30: LVMIN
B31: Curva1 | C31: Convexa | E31: Curva3 | F31: Convexa | H31: Curva5 | I31: Convexa
B32: Lim_Segur | C32: 95 | E32: Lim_Segur | F32: 20 | H32: Lim_Segur | I32: 27
B33: Lim_Opera | C33: =0.6*I6 -> 30 | E33: Lim_Opera | F33: =0.6*50 -> 30 | H33: Lim_Opera | I33: =0.6*50 -> 30
B34: ccv | C34: =P6*((O6/2)/N6)^2 -> -0.32406875 | E34: ccv | F34: =P10*((O10/2)/N10)^2 -> -0.039759375 | H34: ccv | I34: =P14*((O14/2)/N14)^2 -> -0.050625
B36: Curva2 | C36: Concava | E36: Curva4 | F36: Concava | H36: Curva6 | I36: Concava
B37: Lim_Segur | C37: 50 | E37: Lim_Segur | F37: 150 | H37: Lim_Segur | I37: 40
B38: Lim_Opera | C38: =0.6*I10 -> 30 | E38: Lim_Opera | F38: =0.6*50 -> 30 | H38: Lim_Opera | I38: =0.6*50 -> 30
B39: Lim_Como | C39: =((I8)^2*J8)/395 -> 30.21519 | E39: Lim_Como | F39: =((I12)^2*J12)/395 -> 97.727848 | H39: Lim_Como | I39: =((I16)^2*J16)/395 -> 16.759494
B40: ccv | C40: =P8*((O8/2)/N8)^2 -> 0.07459375 | E40: ccv | F40: =P12*((O12/2)/N12)^2 -> 0.77205 | H40: ccv | I40: =P16*((O16/2)/N16)^2 -> 0.0331

Sheet PERFIL
B3: PTOS.CONTROL | C3: ABSCISA | D3: COTA | E3: CONCATENADO | F3: CONCATENADOx10 | G3: SEMEJANZA DE TRIANGULOS PARA INTERPOLACION
B4: PTO.1 | C4: 0 | D4: 1644 | E4: =CONCATENATE(C4,",",D4) -> 0,1644 | F4: =CONCATENATE(C4,",",D4*10) -> 0,16440 | G4: Dist_Inf | H4: Cota_Sum | I4: Dist_Sup | J4: Cota
B5: 1 | C5: 14.507 | D5: 1646 | E5: =CONCATENATE(C5,",",D5) -> 14,507,1646 | F5: =CONCATENATE(C5,",",D5*10) -> 14,507,16460
B6: 2 | C6: 55.671 | D6: 1650 | E6: =CONCATENATE(C6,",",D6) -> 55,671,1650 | F6: =CONCATENATE(C6,",",D6*10) -> 55,671,16500
B7: 3 | C7: 92.286 | D7: 1652 | E7: =CONCATENATE(C7,",",D7) -> 92,286,1652 | F7: =CONCATENATE(C7,",",D7*10) -> 92,286,16520
B8: 4-ESCOR | C8: =C7+1.837 -> 94.123 | D8: =1650+H8 -> 1651.3487 | E8: =CONCATENATE(C8,",",D8) -> 94,123,1651,34873145045 | F8: =CONCATENATE(C8,",",D8*10) -> 94,123,16513,4873145045 | G8: 5.635 | H8: =(J8*G8)/(G8+I8) -> 1.3487315 | I8: 2.721 | J8: 2
B9: 5-ESCOR | C9: 127.473 | D9: =1650+H9 -> 1651.146 | E9: =CONCATENATE(C9,",",D9) -> 127,473,1651,14600753469 | F9: =CONCATENATE(C9,",",D9*10) -> 127,473,16511,4600753469 | G9: 6.236 | H9: =(J9*G9)/(G9+I9) -> 1.1460075 | I9: 4.647 | J9: 2
B10: 6 | C10: =C11-11.954 -> 149.601 | D10: 1648 | E10: =CONCATENATE(C10,",",D10) -> 149,601,1648 | F10: =CONCATENATE(C10,",",D10*10) -> 149,601,16480
B11: 7-PC1 | C11: 161.555 | D11: =1644+H11 -> 1645.4998 | E11: =CONCATENATE(C11,",",D11) -> 161,555,1645,49980776624 | F11: =CONCATENATE(C11,",",D11*10) -> 161,555,16454,9980776624 | G11: 3.901 | H11: =(J11*G11)/(G11+I11) -> 1.4998078 | I11: 1.301 | J11: 2
B12: 8 | C12: =C11+6.56 -> 168.115 | D12: 1644 | E12: =CONCATENATE(C12,",",D12) -> 168,115,1644 | F12: =CONCATENATE(C12,",",D12*10) -> 168,115,16440 | M12: =1900/100 -> 19
B13: 9 | C13: =C12+(7.783/2) -> 172.0065 | D13: =1642+H13 -> 1643.726 | E13: =CONCATENATE(C13,",",D13) -> 172,0065,1643,72596640356 | F13: =CONCATENATE(C13,",",D13*10) -> 172,0065,16437,2596640356 | G13: 8.528 | H13: =(J13*G13)/(G13+I13) -> 1.7259664 | I13: 1.354 | J13: 2
B14: 10 | C14: =C12+7.783 -> 175.898 | D14: 1644 | E14: =CONCATENATE(C14,",",D14) -> 175,898,1644 | F14: =CONCATENATE(C14,",",D14*10) -> 175,898,16440
B15: 11 | C15: =C14+17.319 -> 193.217 | D15: 1648 | E15: =CONCATENATE(C15,",",D15) -> 193,217,1648 | F15: =CONCATENATE(C15,",",D15*10) -> 193,217,16480
B16: 12 | C16: =C15+10.064 -> 203.281 | D16: 1650 | E16: =CONCATENATE(C16,",",D16) -> 203,281,1650 | F16: =CONCATENATE(C16,",",D16*10) -> 203,281,16500
B17: 13 | C17: =C18-1.99 -> 216.822 | D17: =1652+H17 -> 1652 | E17: =CONCATENATE(C17,",",D17) -> 216,822,1652 | F17: =CONCATENATE(C17,",",D17*10) -> 216,822,16520
B18: 14-PT1 | C18: 218.812 | D18: 1652.266 | E18: =CONCATENATE(C18,",",D18) -> 218,812,1652,266 | F18: =CONCATENATE(C18,",",D18*10) -> 218,812,16522,66 | G18: 0.768 | H18: =(J18*G18)/(G18+I18) -> 0.26551426 | I18: 5.017 | J18: 2
B19: 15 | C19: =C18+12.945 -> 231.757 | D19: =1652+H19 -> 1653.7475 | E19: =CONCATENATE(C19,",",D19) -> 231,757,1653,74750957854 | F19: =CONCATENATE(C19,",",D19*10) -> 231,757,16537,4750957854 | G19: 4.561 | H19: =(J19*G19)/(G19+I19) -> 1.7475096 | I19: 0.659 | J19: 2
B20: 16 | C20: =C18+27.882 -> 246.694 | D20: 1652 | E20: =CONCATENATE(C20,",",D20) -> 246,694,1652 | F20: =CONCATENATE(C20,",",D20*10) -> 246,694,16520
B21: 17 | C21: =C20+64.914 -> 311.608 | D21: 1650 | E21: =CONCATENATE(C21,",",D21) -> 311,608,1650 | F21: =CONCATENATE(C21,",",D21*10) -> 311,608,16500 | G21: 2.313 | H21: =(J21*G21)/I21 -> 0.73533619 | I21: 6.291 | J21: 2
B22: 18 | C22: =C21+29.885 -> 341.493 | D22: 1646 | E22: =CONCATENATE(C22,",",D22) -> 341,493,1646 | F22: =CONCATENATE(C22,",",D22*10) -> 341,493,16460
B23: 19 | C23: =C22+8.48 -> 349.973 | D23: =1644+H23 -> 1644.3573 | E23: =CONCATENATE(C23,",",D23) -> 349,973,1644,35733919736 | F23: =CONCATENATE(C23,",",D23*10) -> 349,973,16443,5733919736 | G23: 0.65 | H23: =(J23*G23)/(G23+I23) -> 0.3573392 | I23: 2.988 | J23: 2
B24: 20 | C24: =C22+16.961 -> 358.454 | D24: 1646 | E24: =CONCATENATE(C24,",",D24) -> 358,454,1646 | F24: =CONCATENATE(C24,",",D24*10) -> 358,454,16460
B25: 21 | C25: =C24+5.641 -> 364.095 | D25: =1646+H25 -> 1647.422 | E25: =CONCATENATE(C25,",",D25) -> 364,095,1647,4219858156 | F25: =CONCATENATE(C25,",",D25*10) -> 364,095,16474,219858156 | G25: 2.406 | H25: =(J25*G25)/(G25+I25) -> 1.4219858 | I25: 0.978 | J25: 2
B26: 22 | C26: =C24+11.281 -> 369.735 | D26: 1646 | E26: =CONCATENATE(C26,",",D26) -> 369,735,1646 | F26: =CONCATENATE(C26,",",D26*10) -> 369,735,16460
B27: 23 | C27: =C26+6.681 -> 376.416 | D27: =1644+H27 -> 1645.2349 | E27: =CONCATENATE(C27,",",D27) -> 376,416,1645,23490212412 | F27: =CONCATENATE(C27,",",D27*10) -> 376,416,16452,3490212411 | G27: 2.965 | H27: =(J27*G27)/(G27+I27) -> 1.2349021 | I27: 1.837 | J27: 2
B28: 24 | C28: =C26+13.362 -> 383.097 | D28: 1646 | E28: =CONCATENATE(C28,",",D28) -> 383,097,1646 | F28: =CONCATENATE(C28,",",D28*10) -> 383,097,16460
B29: 25-PC2 | C29: =C28+23.941 -> 407.038 | D29: =1650+H29 -> 1650.8717 | E29: =CONCATENATE(C29,",",D29) -> 407,038,1650,87173100872 | F29: =CONCATENATE(C29,",",D29*10) -> 407,038,16508,7173100872 | G29: 1.05 | H29: =(J29*G29)/(G29+I29) -> 0.87173101 | I29: 1.359 | J29: 2
B30: 26 | C30: =C29+9.57 -> 416.608 | D30: 1654 | E30: =CONCATENATE(C30,",",D30) -> 416,608,1654 | F30: =CONCATENATE(C30,",",D30*10) -> 416,608,16540
B31: 27 | C31: =C30+12.23 -> 428.838 | D31: 1656 | E31: =CONCATENATE(C31,",",D31) -> 428,838,1656 | F31: =CONCATENATE(C31,",",D31*10) -> 428,838,16560
B32: 28 | C32: =C31+19.8 -> 448.638 | D32: 1654 | E32: =CONCATENATE(C32,",",D32) -> 448,638,1654 | F32: =CONCATENATE(C32,",",D32*10) -> 448,638,16540
B33: 29 | C33: =C32+20.13 -> 468.768 | D33: 1648 | E33: =CONCATENATE(C33,",",D33) -> 468,768,1648 | F33: =CONCATENATE(C33,",",D33*10) -> 468,768,16480
B34: 30-ESCOR | C34: =C33+13.24 -> 482.008 | D34: =1642+H34 -> 1643.5619 | E34: =CONCATENATE(C34,",",D34) -> 482,008,1643,56193181818 | F34: =CONCATENATE(C34,",",D34*10) -> 482,008,16435,6193181818 | G34: 5.498 | H34: =(J34*G34)/(G34+I34) -> 1.5619318 | I34: 1.542 | J34: 2
B35: 31-ESCOR | C35: =C34+51.3 -> 533.308 | D35: =1642+H35 -> 1642.4961 | E35: =CONCATENATE(C35,",",D35) -> 533,308,1642,49612264908 | F35: =CONCATENATE(C35,",",D35*10) -> 533,308,16424,9612264908 | G35: 5.566 | H35: =(J35*G35)/(G35+I35) -> 0.49612265 | I35: 16.872 | J35: 2
B36: 32-PT2 | C36: =C35+16.34 -> 549.648 | D36: =1646+H36 -> 1646.2278 | E36: =CONCATENATE(C36,",",D36) -> 549,648,1646,22782967366 | F36: =CONCATENATE(C36,",",D36*10) -> 549,648,16462,2782967366 | G36: 0.939 | H36: =(J36*G36)/(G36+I36) -> 0.22782967 | I36: 7.304 | J36: 2
B37: 33 | C37: =C36+20.786 -> 570.434 | D37: 1642 | E37: =CONCATENATE(C37,",",D37) -> 570,434,1642 | F37: =CONCATENATE(C37,",",D37*10) -> 570,434,16420
B38: 34 | C38: =C37+9.56 -> 579.994 | D38: 1634 | E38: =CONCATENATE(C38,",",D38) -> 579,994,1634 | F38: =CONCATENATE(C38,",",D38*10) -> 579,994,16340
B39: 35 | C39: =C38+24.387 -> 604.381 | D39: 1628 | E39: =CONCATENATE(C39,",",D39) -> 604,381,1628 | F39: =CONCATENATE(C39,",",D39*10) -> 604,381,16280
B40: 36 | C40: =C39+19.813 -> 624.194 | D40: =1626+H40 -> 1626.3693 | E40: =CONCATENATE(C40,",",D40) -> 624,194,1626,36927385477 | F40: =CONCATENATE(C40,",",D40*10) -> 624,194,16263,6927385477 | G40: 1.846 | H40: =(J40*G40)/(G40+I40) -> 0.36927385 | I40: 8.152 | J40: 2
B41: 37 | C41: =C39+39.625 -> 644.006 | D41: 1628 | E41: =CONCATENATE(C41,",",D41) -> 644,006,1628 | F41: =CONCATENATE(C41,",",D41*10) -> 644,006,16280
B42: 38-PC3 | C42: 657.88484 | D42: =1630+H42 -> 1631.9343 | E42: =CONCATENATE(C42,",",D42) -> 657,884841981144,1631,9342958778 | F42: =CONCATENATE(C42,",",D42*10) -> 657,884841981144,16319,342958778 | G42: 4.622 | H42: =(J42*G42)/(G42+I42) -> 1.9342959 | I42: 0.157 | J42: 2
...

Sheet RASANTE
A2: PUNTO | B2: Elementos AH | E2: Elementos AV | F2: ABSCISAS | G2: PENDIENTE TRAMO (%) | H2: PERALTE (e)(%) | J2: Cota tangente eje (msnm) | K2: CCV | L2: Cota Rasante (msnm)
H3: Izquierdo | I3: Derecho | L3: Borde Izquierdo | M3: Eje | N3: Borde Derecho
A4: PTO1 | F4: =AH!W6 -> 0 | G4: =IF(F4<=AV!$T$6,AV!$C$5,IF(RASANTE!F4<=AV!$T$8,AV!$C$7,IF(RASANTE!F4<=AV!$T$10,AV!$C$9,IF(RASANTE!F4<=AV!$T$12,AV!#REF!,IF(RASANTE!F4<=AV!$T$14,AV!$C$11,IF(RASANTE!F4<=AV!$T$16,AV!$C$13, IF(RASANTE!F4<=AV!$T$18,AV!$C$15,IF(RASANTE!F4<=AV!$T$20,AV!$C$19,IF(RASANTE!F4<=AV!$T$22,AV!$C$21,IF(RASANTE!F4<=AV!$T$24,AV!$C$23,AV!$C$25)))))))))) -> 3.142 | H4: =+IF(AND(AH!$H$8="Izquierda",RASANTE!F4<=PERALTE!$AB$6),IF(RASANTE!F4<=PERALTE!$S$6,-2,IF(RASANTE!F4<=PERALTE!$U$6,(-6/(PERALTE!$U$6-PERALTE!$S$6)*(RASANTE!F4-PERALTE!$S$6)-2),IF(RASANTE!F4<=PERALTE!$X$6,-8,IF(RASANTE!F4<=PERALTE!$Z$6,(-6/(PERALTE!$X$6-PERALTE!$Z$6)*(RASANTE!F4-PERALTE!$Z$6)-2),IF(RASANTE!F4<=PERALTE!$AB$6,-2))))),IF(AND(AH!$H$8="Derecha",RASANTE!F4<=PERALTE!$AB$6),IF(RASANTE!F4<=PERALTE!$Q$6,-2,IF(RASANTE!F4<=PERALTE!$U$6,(10/(PERALTE!$U$6-PERALTE!$Q$6)*(RASANTE!F4-PERALTE!$Q$6)-2),IF(RASANTE!F4<=PERALTE!$X$6,8,IF(RASANTE!F4<=PERALTE!$AB$6,(10/(PERALTE!$X$6-PERALTE!$AB$6)*(RASANTE!F4-PERALTE!$AB$6)-2))))),IF(AND(AH!$H$10="Izquierda",RASANTE!F4<=PERALTE!$AB$8),IF(RASANTE!F4<=PERALTE!$S$8,-2,IF(RASANTE!F4<=PERALTE!$U$8,(-6/(PERALTE!$U$8-PERALTE!$S$8)*(RASANTE!F4-PERALTE!$S$8)-2),IF(RASANTE!F4<=PERALTE!$X$8,-8,IF(RASANTE!F4<=PERALTE!$Z$8,(-6/(PERALTE!$X$8-PERALTE!$Z$8)*(RASANTE!F4-PERALTE!$Z$8)-2),IF(RASANTE!F4<=PERALTE!$AB$8,-2))))),IF(AND(AH!$H$10="Derecha",RASANTE!F4<=PERALTE!$AB$8),IF(RASANTE!F4<=PERALTE!$Q$8,-2,IF(RASANTE!F4<=PERALTE!$U$8,(10/(PERALTE!$U$8-PERALTE!$Q$8)*(RASANTE!F4-PERALTE!$Q$8)-2),IF(RASANTE!F4<=PERALTE!$X$8,8,IF(RASANTE!F4<=PERALTE!$AB$8,(10/(PERALTE!$X$8-PERALTE!$AB$8)*(RASANTE!F4-PERALTE!$AB$8)-2))))),IF(AND(AH!$H$12="Izquierda",RASANTE!F4<=PERALTE!$AB$10),IF(RASANTE!F4<=PERALTE!$S$10,-2,IF(RASANTE!F4<=PERALTE!$U$10,(-6/(PERALTE!$U$10-PERALTE!$S$10)*(RASANTE!F4-PERALTE!$S$10)-2),IF(RASANTE!F4<=PERALTE!$X$10,-8,IF(RASANTE!F4<=PERALTE!$Z$10,(-6/(PERALTE!$X$10-PERALTE!$Z$10)*(RASANTE!F4-PERALTE!$Z$10)-2),IF(RASANTE!F4<=PERALTE!$AB$10,-2))))),IF(AND(AH!$H$12="Derecha",RASANTE!F4<=PERALTE!$AB$10),IF(RASANTE!F4<=PERALTE!$Q$10,-2,IF(RASANTE!F4<=PERALTE!$U$10,(10/(PERALTE!$U$10-PERALTE!$Q$10)*(RASANTE!F4-PERALTE!$Q$10)-2),IF(RASANTE!F4<=PERALTE!$X$10,8,IF(RASANTE!F4<=PERALTE!$AB$10,(10/(PERALTE!$X$10-PERALTE!$AB$10)*(RASANTE!F4-PERALTE!$AB$10)-2))))),IF(AND(AH!$H$14="Izquierda",RASANTE!F4<=PERALTE!$AB$12),IF(RASANTE!F4<=PERALTE!$S$12,-2,IF(RASANTE!F4<=PERALTE!$U$12,(-6/(PERALTE!$U$12-PERALTE!$S$12)*(RASANTE!F4-PERALTE!$S$12)-2),IF(RASANTE!F4<=PERALTE!$X$12,-8,IF(RASANTE!F4<=PERALTE!$Z$12,(-6/(PERALTE!$X$12-PERALTE!$Z$12)*(RASANTE!F4-PERALTE!$Z$12)-2),IF(RASANTE!F4<=PERALTE!$AB$12,-2))))),IF(AND(AH!$H$14="Derecha",RASANTE!F4<=PERALTE!$AB$12),IF(RASANTE!F4<=PERALTE!$Q$12,-2,IF(RASANTE!F4<=PERALTE!$U$12,(10/(PERALTE!$U$12-PERALTE!$Q$12)*(RASANTE!F4-PERALTE!$Q$12)-2),IF(RASANTE!F4<=PERALTE!$X$12,8,IF(RASANTE!F4<=PERALTE!$AB$12,(10/(PERALTE!$X$12-PERALTE!$AB$12)*(RASANTE!F4-PERALTE!$AB$12)-2))))),IF(AND(AH!$H$16="Izquierda",RASANTE!F4<=PERALTE!$AB$14),IF(RASANTE!F4<=PERALTE!$S$14,-2,IF(RASANTE!F4<=PERALTE!$U$14,(-6/(PERALTE!$U$14-PERALTE!$S$14)*(RASANTE!F4-PERALTE!$S$14)-2),IF(RASANTE!F4<=PERALTE!$X$14,-8,IF(RASANTE!F4<=PERALTE!$Z$14,(-6/(PERALTE!$X$14-PERALTE!$Z$14)*(RASANTE!F4-PERALTE!$Z$14)-2),IF(RASANTE!F4<=PERALTE!$AB$14,-2))))),IF(AND(AH!$H$16="Derecha",RASANTE!F4<=PERALTE!$AB$14),IF(RASANTE!F4<=PERALTE!$Q$14,-2,IF(RASANTE!F4<=PERALTE!$U$14,(10/(PERALTE!$U$14-PERALTE!$Q$14)*(RASANTE!F4-PERALTE!$Q$14)-2),IF(RASANTE!F4<=PERALTE!$X$14,8,IF(RASANTE!F4<=PERALTE!$AB$14,(10/(PERALTE!$X$14-PERALTE!$AB$14)*(RASANTE!F4-PERALTE!$AB$14)-2))))),IF(AND(AH!$H$18="Izquierda",RASANTE!F4<=PERALTE!$AB$16),IF(RASANTE!F4<=PERALTE!$S$16,-2,IF(RASANTE!F4<=PERALTE!$U$16,(-6/(PERALTE!$U$16-PERALTE!$S$16)*(RASANTE!F4-PERALTE!$S$16)-2),IF(RASANTE!F4<=PERALTE!$X$16,-8,IF(RASANTE!F4<=PERALTE!$Z$16,(-6/(PERALTE!$X$16-PERALTE!$Z$16)*(RASANTE!F4-PERALTE!$Z$16)-2),IF(RASANTE!F4<=PERALTE!$AB$16,-2))))),IF(AND(AH!$H$18="Derecha",RASANTE!F4<=PERALTE!$AB$16),IF(RASANTE!F4<=PERALTE!$Q$16,-2,IF(RASANTE!F4<=PERALTE!$U$16,(10/(PERALTE!$U$16-PERALTE!$Q$16)*(RASANTE!F4-PERALTE!$Q$16)-2),IF(RASANTE!F4<=PERALTE!$X$16,8,IF(RASANTE!F4<=PERALTE!$AB$16,(10/(PERALTE!$X$16-PERALTE!$AB$16)*(RASANTE!F4-PERALTE!$AB$16)-2))))),IF(AND(AH!$H$20="Izquierda",RASANTE!F4<=PERALTE!$AB$18),IF(RASANTE!F4<=PERALTE!$S$18,-2,IF(RASANTE!F4<=PERALTE!$U$18,(-6/(PERALTE!$U$18-PERALTE!$S$18)*(RASANTE!F4-PERALTE!$S$18)-2),IF(RASANTE!F4<=PERALTE!$X$18,-8,IF(RASANTE!F4<=PERALTE!$Z$18,(-6/(PERALTE!$X$18-PERALTE!$Z$18)*(RASANTE!F4-PERALTE!$Z$18)-2),IF(RASANTE!F4<=PERALTE!$AB$18,-2))))),IF(AND(AH!$H$20="Derecha",RASANTE!F4<=PERALTE!$AB$18),IF(RASANTE!F4<=PERALTE!$Q$18,-2,IF(RASANTE!F4<=PERALTE!$U$18,(10/(PERALTE!$U$18-PERALTE!$Q$18)*(RASANTE!F4-PERALTE!$Q$18)-2),IF(RASANTE!F4<=PERALTE!$X$18,8,IF(RASANTE!F4<=PERALTE!$AB$18,(10/(PERALTE!$X$18-PERALTE!$AB$18)*(RASANTE!F4-PERALTE!$AB$18)-2))))),IF(AND(AH!$H$24="Izquierda",RASANTE!F4<=PERALTE!$AB$22),IF(RASANTE!F4<=PERALTE!$S$22,-2,IF(RASANTE!F4<=PERALTE!$U$22,(-6/(PERALTE!$U$22-PERALTE!$S$22)*(RASANTE!F4-PERALTE!$S$22)-2),IF(RASANTE!F4<=PERALTE!$X$22,-8,IF(RASANTE!F4<=PERALTE!$Z$22,(-6/(PERALTE!$X$22-PERALTE!$Z$22)*(RASANTE!F4-PERALTE!$Z$22)-2),IF(RASANTE!F4<=PERALTE!$AB$22,-2))))),IF(AND(AH!$H$24="Derecha",RASANTE!F4<=PERALTE!$AB$22),IF(RASANTE!F4<=PERALTE!$Q$22,-2,IF(RASANTE!F4<=PERALTE!$U$22,(10/(PERALTE!$U$22-PERALTE!$Q$22)*(RASANTE!F4-PERALTE!$Q$22)-2),IF(RASANTE!F4<=PERALTE!$X$22,8,IF(RASANTE!F4<=PERALTE!$AB$22,(10/(PERALTE!$X$22-PERALTE!$AB$22)*(RASANTE!F4-PERALTE!$AB$22)-2))))),IF(AND(AH!#REF!="Izquierda",RASANTE!F4<=PERALTE!#REF!),IF(RASANTE!F4<=PERALTE!#REF!,-2,IF(RASANTE!F4<=PERALTE!#REF!,(-6/(PERALTE!#REF!-PERALTE!#REF!)*(RASANTE!F4-PERALTE!#REF!)-2),IF(RASANTE!F4<=PERALTE!#REF!,-8,IF(RASANTE!F4<=PERALTE!#REF!,(-6/(PERALTE!#REF!-PERALTE!#REF!)*(RASANTE!F4-PERALTE!#REF!)-2),IF(RASANTE!F4<=PERALTE!#REF!,-2))))),IF(AND(AH!#REF!="Derecha",RASANTE!F4<=PERALTE!#REF!),IF(RASANTE!F4<=PERALTE!#REF!,-2,IF(RASANTE!F4<=PERALTE!#REF!,(10/(PERALTE!#REF!-PERALTE!#REF!)*(RASANTE!F4-PERALTE!#REF!)-2),IF(RASANTE!F4<=PERALTE!#REF!,8,IF(RASANTE!F4<=PERALTE!#REF!,(10/(PERALTE!#REF!-PERALTE!#REF!)*(RASANTE!F4-PERALTE!#REF!)-2))))),IF(AND(AH!#REF!="Izquierda",RASANTE!F4<=PERALTE!$AB$26),IF(RASANTE!F4<=PERALTE!$S$26,-2,IF(RASANTE!F4<=PERALTE!$U$26,(-6/(PERALTE!$U$26-PERALTE!$S$26)*(RASANTE!F4-PERALTE!$S$26)-2),IF(RASANTE!F4<=PERALTE!$X$26,-8,IF(RASANTE!F4<=PERALTE!$Z$26,(-6/(PERALTE!$X$26-PERALTE!$Z$26)*(RASANTE!F4-PERALTE!$Z$26)-2),IF(RASANTE!F4<=PERALTE!$AB$26,-2))))),IF(AND(AH!#REF!="Derecha",RASANTE!F4<=PERALTE!$AB$26),IF(RASANTE!F4<=PERALTE!$Q$26,-2,IF(RASANTE!F4<=PERALTE!$U$26,(10/(PERALTE!$U$26-PERALTE!$Q$26)*(RASANTE!F4-PERALTE!$Q$26)-2),IF(RASANTE!F4<=PERALTE!$X$26,8,IF(RASANTE!F4<=PERALTE!$AB$26,(10/(PERALTE!$X$26-PERALTE!$AB$26)*(RASANTE!F4-PERALTE!$AB$26)-2))))),IF(F4<=PERALTE!#REF!,-2,"Abscisa fuera de la vía"))))))))))))))))))))) -> -2 | I4: =+IF(AND(AH!$H$8="Derecha",RASANTE!F4<=PERALTE!$AB$6),IF(RASANTE!F4<=PERALTE!$S$6,-2,IF(RASANTE!F4<=PERALTE!$U$6,(-6/(PERALTE!$U$6-PERALTE!$S$6)*(RASANTE!F4-PERALTE!$S$6)-2),IF(RASANTE!F4<=PERALTE!$X$6,-8,IF(RASANTE!F4<=PERALTE!$Z$6,(-6/(PERALTE!$X$6-PERALTE!$Z$6)*(RASANTE!F4-PERALTE!$Z$6)-2),IF(RASANTE!F4<=PERALTE!$AB$6,-2))))),IF(AND(AH!$H$8="Izquierda",RASANTE!F4<=PERALTE!$AB$6),IF(RASANTE!F4<=PERALTE!$Q$6,-2,IF(RASANTE!F4<=PERALTE!$U$6,(10/(PERALTE!$U$6-PERALTE!$Q$6)*(RASANTE!F4-PERALTE!$Q$6)-2),IF(RASANTE!F4<=PERALTE!$X$6,8,IF(RASANTE!F4<=PERALTE!$AB$6,(10/(PERALTE!$X$6-PERALTE!$AB$6)*(RASANTE!F4-PERALTE!$AB$6)-2))))),IF(AND(AH!$H$10="Derecha",RASANTE!F4<=PERALTE!$AB$8),IF(RASANTE!F4<=PERALTE!$S$8,-2,IF(RASANTE!F4<=PERALTE!$U$8,(-6/(PERALTE!$U$8-PERALTE!$S$8)*(RASANTE!F4-PERALTE!$S$8)-2),IF(RASANTE!F4<=PERALTE!$X$8,-8,IF(RASANTE!F4<=PERALTE!$Z$8,(-6/(PERALTE!$X$8-PERALTE!$Z$8)*(RASANTE!F4-PERALTE!$Z$8)-2),IF(RASANTE!F4<=PERALTE!$AB$8,-2))))),IF(AND(AH!$H$10="Izquierda",RASANTE!F4<=PERALTE!$AB$8),IF(RASANTE!F4<=PERALTE!$Q$8,-2,IF(RASANTE!F4<=PERALTE!$U$8,(10/(PERALTE!$U$8-PERALTE!$Q$8)*(RASANTE!F4-PERALTE!$Q$8)-2),IF(RASANTE!F4<=PERALTE!$X$8,8,IF(RASANTE!F4<=PERALTE!$AB$8,(10/(PERALTE!$X$8-PERALTE!$AB$8)*(RASANTE!F4-PERALTE!$AB$8)-2))))),IF(AND(AH!$H$12="Derecha",RASANTE!F4<=PERALTE!$AB$10),IF(RASANTE!F4<=PERALTE!$S$10,-2,IF(RASANTE!F4<=PERALTE!$U$10,(-6/(PERALTE!$U$10-PERALTE!$S$10)*(RASANTE!F4-PERALTE!$S$10)-2),IF(RASANTE!F4<=PERALTE!$X$10,-8,IF(RASANTE!F4<=PERALTE!$Z$10,(-6/(PERALTE!$X$10-PERALTE!$Z$10)*(RASANTE!F4-PERALTE!$Z$10)-2),IF(RASANTE!F4<=PERALTE!$AB$10,-2))))),IF(AND(AH!$H$12="Izquierda",RASANTE!F4<=PERALTE!$AB$10),IF(RASANTE!F4<=PERALTE!$Q$10,-2,IF(RASANTE!F4<=PERALTE!$U$10,(10/(PERALTE!$U$10-PERALTE!$Q$10)*(RASANTE!F4-PERALTE!$Q$10)-2),IF(RASANTE!F4<=PERALTE!$X$10,8,IF(RASANTE!F4<=PERALTE!$AB$10,(10/(PERALTE!$X$10-PERALTE!$AB$10)*(RASANTE!F4-PERALTE!$AB$10)-2))))),IF(AND(AH!$H$14="Derecha",RASANTE!F4<=PERALTE!$AB$12),IF(RASANTE!F4<=PERALTE!$S$12,-2,IF(RASANTE!F4<=PERALTE!$U$12,(-6/(PERALTE!$U$12-PERALTE!$S$12)*(RASANTE!F4-PERALTE!$S$12)-2),IF(RASANTE!F4<=PERALTE!$X$12,-8,IF(RASANTE!F4<=PERALTE!$Z$12,(-6/(PERALTE!$X$12-PERALTE!$Z$12)*(RASANTE!F4-PERALTE!$Z$12)-2),IF(RASANTE!F4<=PERALTE!$AB$12,-2))))),IF(AND(AH!$H$14="Izquierda",RASANTE!F4<=PERALTE!$AB$12),IF(RASANTE!F4<=PERALTE!$Q$12,-2,IF(RASANTE!F4<=PERALTE!$U$12,(10/(PERALTE!$U$12-PERALTE!$Q$12)*(RASANTE!F4-PERALTE!$Q$12)-2),IF(RASANTE!F4<=PERALTE!$X$12,8,IF(RASANTE!F4<=PERALTE!$AB$12,(10/(PERALTE!$X$12-PERALTE!$AB$12)*(RASANTE!F4-PERALTE!$AB$12)-2))))),IF(AND(AH!$H$16="Derecha",RASANTE!F4<=PERALTE!$AB$14),IF(RASANTE!F4<=PERALTE!$S$14,-2,IF(RASANTE!F4<=PERALTE!$U$14,(-6/(PERALTE!$U$14-PERALTE!$S$14)*(RASANTE!F4-PERALTE!$S$14)-2),IF(RASANTE!F4<=PERALTE!$X$14,-8,IF(RASANTE!F4<=PERALTE!$Z$14,(-6/(PERALTE!$X$14-PERALTE!$Z$14)*(RASANTE!F4-PERALTE!$Z$14)-2),IF(RASANTE!F4<=PERALTE!$AB$14,-2))))),IF(AND(AH!$H$16="Izquierda",RASANTE!F4<=PERALTE!$AB$14),IF(RASANTE!F4<=PERALTE!$Q$14,-2,IF(RASANTE!F4<=PERALTE!$U$14,(10/(PERALTE!$U$14-PERALTE!$Q$14)*(RASANTE!F4-PERALTE!$Q$14)-2),IF(RASANTE!F4<=PERALTE!$X$14,8,IF(RASANTE!F4<=PERALTE!$AB$14,(10/(PERALTE!$X$14-PERALTE!$AB$14)*(RASANTE!F4-PERALTE!$AB$14)-2))))),IF(AND(AH!$H$18="Derecha",RASANTE!F4<=PERALTE!$AB$16),IF(RASANTE!F4<=PERALTE!$S$16,-2,IF(RASANTE!F4<=PERALTE!$U$16,(-6/(PERALTE!$U$16-PERALTE!$S$16)*(RASANTE!F4-PERALTE!$S$16)-2),IF(RASANTE!F4<=PERALTE!$X$16,-8,IF(RASANTE!F4<=PERALTE!$Z$16,(-6/(PERALTE!$X$16-PERALTE!$Z$16)*(RASANTE!F4-PERALTE!$Z$16)-2),IF(RASANTE!F4<=PERALTE!$AB$16,-2))))),IF(AND(AH!$H$18="Izquierda",RASANTE!F4<=PERALTE!$AB$16),IF(RASANTE!F4<=PERALTE!$Q$16,-2,IF(RASANTE!F4<=PERALTE!$U$16,(10/(PERALTE!$U$16-PERALTE!$Q$16)*(RASANTE!F4-PERALTE!$Q$16)-2),IF(RASANTE!F4<=PERALTE!$X$16,8,IF(RASANTE!F4<=PERALTE!$AB$16,(10/(PERALTE!$X$16-PERALTE!$AB$16)*(RASANTE!F4-PERALTE!$AB$16)-2))))),IF(AND(AH!$H$20="Derecha",RASANTE!F4<=PERALTE!$AB$18),IF(RASANTE!F4<=PERALTE!$S$18,-2,IF(RASANTE!F4<=PERALTE!$U$18,(-6/(PERALTE!$U$18-PERALTE!$S$18)*(RASANTE!F4-PERALTE!$S$18)-2),IF(RASANTE!F4<=PERALTE!$X$18,-8,IF(RASANTE!F4<=PERALTE!$Z$18,(-6/(PERALTE!$X$18-PERALTE!$Z$18)*(RASANTE!F4-PERALTE!$Z$18)-2),IF(RASANTE!F4<=PERALTE!$AB$18,-2))))),IF(AND(AH!$H$20="Izquierda",RASANTE!F4<=PERALTE!$AB$18),IF(RASANTE!F4<=PERALTE!$Q$18,-2,IF(RASANTE!F4<=PERALTE!$U$18,(10/(PERALTE!$U$18-PERALTE!$Q$18)*(RASANTE!F4-PERALTE!$Q$18)-2),IF(RASANTE!F4<=PERALTE!$X$18,8,IF(RASANTE!F4<=PERALTE!$AB$18,(10/(PERALTE!$X$18-PERALTE!$AB$18)*(RASANTE!F4-PERALTE!$AB$18)-2))))),IF(AND(AH!$H$24="Derecha",RASANTE!F4<=PERALTE!$AB$22),IF(RASANTE!F4<=PERALTE!$S$22,-2,IF(RASANTE!F4<=PERALTE!$U$22,(-6/(PERALTE!$U$22-PERALTE!$S$22)*(RASANTE!F4-PERALTE!$S$22)-2),IF(RASANTE!F4<=PERALTE!$X$22,-8,IF(RASANTE!F4<=PERALTE!$Z$22,(-6/(PERALTE!$X$22-PERALTE!$Z$22)*(RASANTE!F4-PERALTE!$Z$22)-2),IF(RASANTE!F4<=PERALTE!$AB$22,-2))))),IF(AND(AH!$H$24="Izquierda",RASANTE!F4<=PERALTE!$AB$22),IF(RASANTE!F4<=PERALTE!$Q$22,-2,IF(RASANTE!F4<=PERALTE!$U$22,(10/(PERALTE!$U$22-PERALTE!$Q$22)*(RASANTE!F4-PERALTE!$Q$22)-2),IF(RASANTE!F4<=PERALTE!$X$22,8,IF(RASANTE!F4<=PERALTE!$AB$22,(10/(PERALTE!$X$22-PERALTE!$AB$22)*(RASANTE!F4-PERALTE!$AB$22)-2))))),IF(AND(AH!#REF!="Derecha",RASANTE!F4<=PERALTE!#REF!),IF(RASANTE!F4<=PERALTE!#REF!,-2,IF(RASANTE!F4<=PERALTE!#REF!,(-6/(PERALTE!#REF!-PERALTE!#REF!)*(RASANTE!F4-PERALTE!#REF!)-2),IF(RASANTE!F4<=PERALTE!#REF!,-8,IF(RASANTE!F4<=PERALTE!#REF!,(-6/(PERALTE!#REF!-PERALTE!#REF!)*(RASANTE!F4-PERALTE!#REF!)-2),IF(RASANTE!F4<=PERALTE!#REF!,-2))))),IF(AND(AH!#REF!="Izquierda",RASANTE!F4<=PERALTE!#REF!),IF(RASANTE!F4<=PERALTE!#REF!,-2,IF(RASANTE!F4<=PERALTE!#REF!,(10/(PERALTE!#REF!-PERALTE!#REF!)*(RASANTE!F4-PERALTE!#REF!)-2),IF(RASANTE!F4<=PERALTE!#REF!,8,IF(RASANTE!F4<=PERALTE!#REF!,(10/(PERALTE!#REF!-PERALTE!#REF!)*(RASANTE!F4-PERALTE!#REF!)-2))))),IF(AND(AH!#REF!="Derecha",RASANTE!F4<=PERALTE!$AB$26),IF(RASANTE!F4<=PERALTE!$S$26,-2,IF(RASANTE!F4<=PERALTE!$U$26,(-6/(PERALTE!$U$26-PERALTE!$S$26)*(RASANTE!F4-PERALTE!$S$26)-2),IF(RASANTE!F4<=PERALTE!$X$26,-8,IF(RASANTE!F4<=PERALTE!$Z$26,(-6/(PERALTE!$X$26-PERALTE!$Z$26)*(RASANTE!F4-PERALTE!$Z$26)-2),IF(RASANTE!F4<=PERALTE!$AB$26,-2))))),IF(AND(AH!#REF!="Izquierda",RASANTE!F4<=PERALTE!$AB$26),IF(RASANTE!F4<=PERALTE!$Q$26,-2,IF(RASANTE!F4<=PERALTE!$U$26,(10/(PERALTE!$U$26-PERALTE!$Q$26)*(RASANTE!F4-PERALTE!$Q$26)-2),IF(RASANTE!F4<=PERALTE!$X$26,8,IF(RASANTE!F4<=PERALTE!$AB$26,(10/(PERALTE!$X$26-PERALTE!$AB$26)*(RASANTE!F4-PERALTE!$AB$26)-2))))),IF(F4<=PERALTE!#REF!,-2,"Abscisa fuera de la vía"))))))))))))))))))))) -> -2 | J4: =AV!W4 -> 1644 | K4: =+IF(AND(AV!$S$6<F4,F4<=AV!$T$6),AV!$P$6*((AV!$S$6-RASANTE!F4)/(AV!$N$6))^2,IF(AND(AV!$T$6<RASANTE!F4,F4<AV!$U$6),AV!$P$6*((AV!$U$6-RASANTE!F4)/(AV!$O$6))^2,IF(AND(AV!$S$8<F4,F4<=AV!$T$8),AV!$P$8*((AV!$S$8-RASANTE!F4)/(AV!$N$8))^2,IF(AND(AV!$T$8<RASANTE!F4,F4<AV!$U$8),AV!$P$8*((AV!$U$8-RASANTE!F4)/(AV!$O$8))^2,IF(AND(AV!$S$10<F4,F4<=AV!$T$10),AV!$P$10*((AV!$S$10-RASANTE!F4)/(AV!$N$10))^2,IF(AND(AV!$T$10<RASANTE!F4,F4<AV!$U$10),AV!$P$10*((AV!$U$10-RASANTE!F4)/(AV!$O$10))^2,IF(AND(AV!$S$12<F4,F4<=AV!$T$12),AV!$P$12*((AV!$S$12-RASANTE!F4)/(AV!$N$12))^2,IF(AND(AV!$T$12<RASANTE!F4,F4<AV!$U$12),AV!$P$12*((AV!$U$12-RASANTE!F4)/(AV!$O$12))^2,IF(AND(AV!$S$14<F4,F4<=AV!$T$14),AV!$P$14*((AV!$S$14-RASANTE!F4)/(AV!$N$14))^2,IF(AND(AV!$T$14<RASANTE!F4,F4<AV!$U$14),AV!$P$14*((AV!$U$14-RASANTE!F4)/(AV!$O$14))^2,IF(AND(AV!$S$16<F4,F4<=AV!$T$16),AV!$P$16*((AV!$S$16-RASANTE!F4)/(AV!$N$16))^2,IF(AND(AV!$T$16<RASANTE!F4,F4<AV!$U$16),AV!$P$16*((AV!$U$16-RASANTE!F4)/(AV!$O$16))^2,IF(AND(AV!$S$18<F4,F4<=AV!$T$18),AV!$P$18*((AV!$S$18-RASANTE!F4)/(AV!$N$18))^2,IF(AND(AV!$T$18<RASANTE!F4,F4<AV!$U$18),AV!$P$18*((AV!$U$18-RASANTE!F4)/(AV!$O$18))^2,IF(AND(AV!$S$20<F4,F4<=AV!$T$20),AV!$P$20*((AV!$S$20-RASANTE!F4)/(AV!$N$20))^2,IF(AND(AV!$T$20<RASANTE!F4,F4<AV!$U$20),AV!$P$20*((AV!$U$20-RASANTE!F4)/(AV!$O$20))^2,IF(AND(AV!$S$22<F4,F4<=AV!$T$22),AV!$P$22*((AV!$S$22-RASANTE!F4)/(AV!$N$22))^2,IF(AND(AV!$T$22<RASANTE!F4,F4<AV!$U$22),AV!$P$22*((AV!$U$22-RASANTE!F4)/(AV!$O$22))^2,IF(AND(AV!$S$24<F4,F4<=AV!$T$24),AV!$P$24*((AV!$S$24-RASANTE!F4)/(AV!$N$24))^2,IF(AND(AV!$T$24<RASANTE!F4,F4<AV!$U$24),AV!$P$24*((AV!$U$24-RASANTE!F4)/(AV!$O$24))^2,0)))))))))))))))))))) -> 0 | L4: =+M4+H4%*PERALTE!$C$32 -> 1643.93 | M4: =J4+K4 -> 1644 | N4: =+M4+I4%*PERALTE!$C$32 -> 1643.93
